Workbook
Name ProductCodes: product_lookup!$A$2:$A$4916
Name ProductList: product_lookup!$I$2:$I$4916

Sheet Excel Decision Model
A1: Retail Pricing | Elasticity & Revenue Scenario Model
A3: Product Selection | D3: Decision Summary
A4: Product | B4: INFLATABLE POLITICAL GLOBE [10002]
A5: Stock Code | B5: =_xlfn.XLOOKUP(B4,product_lookup!I:I,product_lookup!A:A,"") -> 10002 | D5: Product | E5: =B6 -> INFLATABLE POLITICAL GLOBE
A6: Product Description | B6: =_xlfn.XLOOKUP(B4,product_lookup!I:I,product_lookup!B:B,"") -> INFLATABLE POLITICAL GLOBE | D6: Price Change | E6: =B13 -> 0.1
A7: Typical Price | B7: =_xlfn.XLOOKUP(B4,product_lookup!I:I,product_lookup!C:C,"") -> 0.86 | D7: Quantity Impact | E7: =B15 -> -0.2290571
A8: Typical Monthly Units | B8: =_xlfn.XLOOKUP(B4,product_lookup!I:I,product_lookup!D:D,"") -> 340 | D8: Revenue Impact | E8: =B22 -> -0.15196281
A9: Sales Volume Tier | B9: =_xlfn.XLOOKUP(B4,product_lookup!I:I,product_lookup!H:H,"") -> High Volume | D9: Monthly Revenue Δ | E9: =B21 -> -44.433925
A10: Estimated Price Elasticity | B10: =_xlfn.XLOOKUP(B9,elasticity_estimates!A:A,elasticity_estimates!B:B,"") -> -2.7294143
D11: Model Interpretation | E11: =IF(B13=0,"No price change entered",IF(B22>0,"Scenario increases estimated revenue",IF(B22<0,"Scenario decreases estimated revenue","No estimated revenue change"))) -> Scenario decreases estimated revenue
A12: Pricing Scenario
A13: Proposed Price Change | B13: 0.1 | D13: Price Scenario Comparison | E13: -0.1 | F13: -0.05 | G13: Current | H13: 0.05 | I13: 0.1
A14: New Price | B14: =B7*(1+B13) -> 0.946 | D14: New Price | E14: =$B$7*(1+E$13) -> 0.774 | F14: =$B$7*(1+F$13) -> 0.817 | G14: =$B$7 -> 0.86 | H14: =$B$7*(1+H$13) -> 0.903 | I14: =$B$7*(1+I$13) -> 0.946
A15: Implied Quantity Change | B15: =(1+B13)^B10-1 -> -0.2290571 | D15: Est. Units | E15: =$B$8*(1+E$13)^$B$10 -> 453.28366 | F15: =$B$8*(1+F$13)^$B$10 -> 391.09335 | G15: =$B$8 -> 340 | H15: =$B$8*(1+H$13)^$B$10 -> 297.60796 | I15: =$B$8*(1+I$13)^$B$10 -> 262.12059
A16: Estimated Monthly Units | B16: =B8*(1+B15) -> 262.12059 | D16: Revenue | E16: =E14*E15 -> 350.84155 | F16: =F14*F15 -> 319.52326 | G16: =$B$19 -> 292.4 | H16: =H14*H15 -> 268.73999 | I16: =I14*I15 -> 247.96608
D17: Revenue Δ % | E17: =E16/$B$19-1 -> 0.19986851 | F17: =F16/$B$19-1 -> 0.092760819 | G17: =0% -> 0 | H17: =H16/$B$19-1 -> -0.080916597 | I17: =I16/$B$19-1 -> -0.15196281
A18: Revenue Impact
A19: Baseline Monthly Revenue | B19: =B7*B8 -> 292.4
A20: Estimated New Monthly Revenue | B20: =B14*B16 -> 247.96608
A21: Revenue Change | B21: =B20-B19 -> -44.433925
A22: Revenue Change (%) | B22: =B20/B19-1 -> -0.15196281
D25: Price Change | E25: -0.1 | F25: -0.05 | G25: 0 | H25: 0.05 | I25: 0.1
D26: Revenue Change | E26: =E17 -> 0.19986851 | F26: =F17 -> 0.092760819 | G26: =G17 -> 0 | H26: =H17 -> -0.080916597 | I26: =I17 -> -0.15196281
D33: Model Methodology & Limitations
D34: Methodology Elasticity estimates are derived from log-log regressions with product and month fixed effects, clustered standard errors by product, and price-outlier trimming.
D38: Interpretation Scenario results apply estimated volume-tier elasticities to hypothetical price changes using a constant-elasticity formula. They are not causal forecasts.
D42: Limitations Estimates do not account for product costs, profit margins, competitor responses, inventory constraints, or other factors affecting pricing decisions.

Sheet revenue_scenarios
A1: volume_tier | B1: elasticity | C1: price_change | D1: price_ratio | E1: quantity_ratio | F1: quantity_change | G1: revenue_ratio | H1: revenue_change
A2: Low Volume | B2: -2 | C2: -0.2 | D2: 0.8 | E2: 1.5625 | F2: 0.5625 | G2: 1.25 | H2: 0.25
A3: Low Volume | B3: -2 | C3: -0.15 | D3: 0.85 | E3: 1.384083 | F3: 0.38408304 | G3: 1.1764706 | H3: 0.17647059
A4: Low Volume | B4: -2 | C4: -0.1 | D4: 0.9 | E4: 1.2345679 | F4: 0.2345679 | G4: 1.1111111 | H4: 0.11111111
A5: Low Volume | B5: -2 | C5: -0.05 | D5: 0.95 | E5: 1.1080332 | F5: 0.10803324 | G5: 1.0526316 | H5: 0.052631579
A6: Low Volume | B6: -2 | C6: 0 | D6: 1 | E6: 1 | F6: 0 | G6: 1 | H6: 0
A7: Low Volume | B7: -2 | C7: 0.05 | D7: 1.05 | E7: 0.90702948 | F7: -0.092970522 | G7: 0.95238095 | H7: -0.047619048
A8: Low Volume | B8: -2 | C8: 0.1 | D8: 1.1 | E8: 0.82644628 | F8: -0.17355372 | G8: 0.90909091 | H8: -0.090909091
A9: Low Volume | B9: -2 | C9: 0.15 | D9: 1.15 | E9: 0.75614367 | F9: -0.24385633 | G9: 0.86956522 | H9: -0.13043478
A10: Low Volume | B10: -2 | C10: 0.2 | D10: 1.2 | E10: 0.69444444 | F10: -0.30555556 | G10: 0.83333333 | H10: -0.16666667
A11: Mid Volume | B11: -2.47 | C11: -0.2 | D11: 0.8 | E11: 1.7352727 | F11: 0.73527269 | G11: 1.3882182 | H11: 0.38821815
A12: Mid Volume | B12: -2.47 | C12: -0.15 | D12: 0.85 | E12: 1.4939472 | F12: 0.49394722 | G12: 1.2698551 | H12: 0.26985513
A13: Mid Volume | B13: -2.47 | C13: -0.1 | D13: 0.9 | E13: 1.297242 | F13: 0.297242 | G13: 1.1675178 | H13: 0.1675178
... A28: High Volume | B28: -2.73 | C28: 0.2 | D28: 1.2 | E28: 0.60790428 | F28: -0.39209572 | G28: 0.72948513 | H28: -0.27051487

Sheet elasticity_estimates
A1: volume_tier | B1: elasticity | C1: se | D1: lower_ci | E1: upper_ci
A2: Low Volume | B2: -1.9995266 | C2: 0.044427729 | D2: -2.0866049 | E2: -1.9124482
A3: Mid Volume | B3: -2.4682982 | C3: 0.033853815 | D3: -2.5346516 | E3: -2.4019447
A4: High Volume | B4: -2.7294143 | C4: 0.087810554 | D4: -2.901523 | E4: -2.5573056

Sheet product_lookup
A1: stock_code | B1: description | C1: typical_price | D1: typical_monthly_units | E1: avg_monthly_units | F1: months_observed | G1: total_revenue | H1: volume_tier | I1: product_selector
A2: 10002 | B2: INFLATABLE POLITICAL GLOBE | C2: 0.86 | D2: 340 | E2: 510.05882 | F2: 17 | G2: 6942.26 | H2: High Volume | I2: =B2&" ["&A2&"]" -> INFLATABLE POLITICAL GLOBE [10002]
A3: 10002R | B3: ROBOT PENCIL SHARPNER | C3: 5.115 | D3: 2 | E3: 2 | F3: 2 | G3: 20.57 | H3: Low Volume | I3: =B3&" ["&A3&"]" -> ROBOT PENCIL SHARPNER [10002R]
A4: 10080 | B4: GROOVY CACTUS INFLATABLE | C4: 0.39 | D4: 6 | E4: 28.636364 | F4: 11 | G4: 129.29 | H4: Low Volume | I4: =B4&" ["&A4&"]" -> GROOVY CACTUS INFLATABLE [10080]
A5: 10109 | B5: BENDY COLOUR PENCILS | C5: 0.42 | D5: 4 | E5: 4 | F5: 1 | G5: 1.68 | H5: Low Volume | I5: =B5&" ["&A5&"]" -> BENDY COLOUR PENCILS [10109]
A6: 10120 | B6: DOGGY RUBBER | C6: 0.21 | D6: 28 | E6: 31.619048 | F6: 21 | G6: 142.74 | H6: Mid Volume | I6: =B6&" ["&A6&"]" -> DOGGY RUBBER [10120]
A7: 10123C | B7: HEARTS WRAPPING TAPE | C7: 0.65 | D7: 14.5 | E7: 25.5 | F7: 12 | G7: 200.1 | H7: Mid Volume | I7: =B7&" ["&A7&"]" -> HEARTS WRAPPING TAPE [10123C]
A8: 10123G | B8: ARMY CAMO WRAPPING TAPE | C8: 0.65 | D8: 18 | E8: 13.666667 | F8: 3 | G8: 29.68 | H8: Mid Volume | I8: =B8&" ["&A8&"]" -> ARMY CAMO WRAPPING TAPE [10123G]
A9: 10124A | B9: SPOTS ON RED BOOKCOVER TAPE | C9: 0.42 | D9: 3.5 | E9: 4.8333333 | F9: 12 | G9: 24.36 | H9: Low Volume | I9: =B9&" ["&A9&"]" -> SPOTS ON RED BOOKCOVER TAPE [10124A]
A10: 10124G | B10: ARMY CAMO BOOKCOVER TAPE | C10: 0.42 | D10: 4 | E10: 3.6666667 | F10: 9 | G10: 14.28 | H10: Low Volume | I10: =B10&" ["&A10&"]" -> ARMY CAMO BOOKCOVER TAPE [10124G]
A11: 10125 | B11: MINI FUNKY DESIGN TAPES | C11: 0.85 | D11: 85 | E11: 91.434783 | F11: 23 | G11: 1715.78 | H11: High Volume | I11: =B11&" ["&A11&"]" -> MINI FUNKY DESIGN TAPES [10125]
A12: 10133 | B12: COLOURING PENCILS BROWN TUBE | C12: 0.85 | D12: 84.5 | E12: 174.40909 | F12: 22 | G12: 2373.26 | H12: High Volume | I12: =B12&" ["&A12&"]" -> COLOURING PENCILS BROWN TUBE [10133]
A13: 10134 | B13: COLOURING PENCILS BROWN TUBE | C13: 1.25 | D13: 28 | E13: 52.083333 | F13: 12 | G13: 721.13 | H13: Mid Volume | I13: =B13&" ["&A13&"]" -> COLOURING PENCILS BROWN TUBE [10134]
A14: 10135 | B14: COLOURING PENCILS BROWN TUBE | C14: 1.25 | D14: 84 | E14: 169.04 | F14: 25 | G14: 4566.21 | H14: High Volume | I14: =B14&" ["&A14&"]" -> COLOURING PENCILS BROWN TUBE [10135]
A15: 10138 | B15: ASSORTED COLOUR JUMBO PEN | C15: 0.42 | D15: 21 | E15: 52.2 | F15: 5 | G15: 111.22 | H15: Mid Volume | I15: =B15&" ["&A15&"]" -> ASSORTED COLOUR JUMBO PEN [10138]
A16: 11001 | B16: ASSTD DESIGN RACING CAR PEN | C16: 1.69 | D16: 96 | E16: 193.16 | F16: 25 | G16: 7408.65 | H16: High Volume | I16: =B16&" ["&A16&"]" -> ASSTD DESIGN RACING CAR PEN [11001]
A17: 15030 | B17: FAN BLACK FRAME | C17: 0.29 | D17: 10 | E17: 14.941176 | F17: 17 | G17: 73.66 | H17: Low Volume | I17: =B17&" ["&A17&"]" -> FAN BLACK FRAME [15030]
A18: 15034 | B18: PAPER POCKET TRAVELING FAN | C18: 0.16 | D18: 289.5 | E18: 446.27273 | F18: 22 | G18: 1263.53 | H18: High Volume | I18: =B18&" ["&A18&"]" -> PAPER POCKET TRAVELING FAN [15034]
A19: 15036 | B19: ASSORTED COLOURS SILK FAN | C19: 0.75 | D19: 1427 | E19: 1770.88 | F19: 25 | G19: 32967.03 | H19: High Volume | I19: =B19&" ["&A19&"]" -> ASSORTED COLOURS SILK FAN [15036]
A20: 15039 | B20: SANDALWOOD FAN | C20: 0.97 | D20: 134 | E20: 204.04 | F20: 25 | G20: 4345.62 | H20: High Volume | I20: =B20&" ["&A20&"]" -> SANDALWOOD FAN [15039]
A21: 15044A | B21: PINK PAPER PARASOL | C21: 3.11 | D21: 32 | E21: 198.56 | F21: 25 | G21: 13210.85 | H21: Mid Volume | I21: =B21&" ["&A21&"]" -> PINK PAPER PARASOL [15044A]
A22: 15044B | B22: BLUE PAPER PARASOL | C22: 2.95 | D22: 25 | E22: 79.52381 | F22: 21 | G22: 4644.13 | H22: Mid Volume | I22: =B22&" ["&A22&"]" -> BLUE PAPER PARASOL [15044B]
A23: 15044C | B23: PURPLE PAPER PARASOL | C23: 3.22 | D23: 17 | E23: 38.68 | F23: 25 | G23: 3027.26 | H23: Mid Volume | I23: =B23&" ["&A23&"]" -> PURPLE PAPER PARASOL [15044C]
A24: 15044D | B24: RED PAPER PARASOL | C24: 3.03 | D24: 35 | E24: 63.84 | F24: 25 | G24: 4559.65 | H24: Mid Volume | I24: =B24&" ["&A24&"]" -> RED PAPER PARASOL [15044D]
A25: 15056BL | B25: EDWARDIAN PARASOL BLACK | C25: 5.5 | D25: 205 | E25: 380.16 | F25: 25 | G25: 47267.45 | H25: High Volume | I25: =B25&" ["&A25&"]" -> EDWARDIAN PARASOL BLACK [15056BL]
A26: 15056N | B26: EDWARDIAN PARASOL NATURAL | C26: 5.58 | D26: 402 | E26: 451.44 | F26: 25 | G26: 57975.45 | H26: High Volume | I26: =B26&" ["&A26&"]" -> EDWARDIAN PARASOL NATURAL [15056N]
A27: 15056P | B27: EDWARDIAN PARASOL PINK | C27: 5.75 | D27: 60 | E27: 98.92 | F27: 25 | G27: 12228.92 | H27: Mid Volume | I27: =B27&" ["&A27&"]" -> EDWARDIAN PARASOL PINK [15056P]
A28: 15056bl | B28: EDWARDIAN PARASOL BLACK | C28: 12.46 | D28: 5.5 | E28: 5.8 | F28: 20 | G28: 1456.32 | H28: Low Volume | I28: =B28&" ["&A28&"]" -> EDWARDIAN PARASOL BLACK [15056bl]
A29: 15056n | B29: EDWARDIAN PARASOL NATURAL | C29: 12.46 | D29: 10 | E29: 10.176471 | F29: 17 | G29: 2170.4 | H29: Low Volume | I29: =B29&" ["&A29&"]" -> EDWARDIAN PARASOL NATURAL [15056n]
A30: 15056p | B30: EDWARDIAN PARASOL PINK | C30: 12.46 | D30: 2 | E30: 2.5555556 | F30: 18 | G30: 577.84 | H30: Low Volume | I30: =B30&" ["&A30&"]" -> EDWARDIAN PARASOL PINK [15056p]
A31: 15058A | B31: BLUE WHITE SPOTS GARDEN PARASOL | C31: 7.995 | D31: 10 | E31: 26.444444 | F31: 18 | G31: 3153.73 | H31: Low Volume | I31: =B31&" ["&A31&"]" -> BLUE WHITE SPOTS GARDEN PARASOL [15058A]
A32: 15058B | B32: PINK WHITE SPOTS GARDEN PARASOL | C32: 7.95 | D32: 8 | E32: 23 | F32: 19 | G32: 3302.71 | H32: Low Volume | I32: =B32&" ["&A32&"]" -> PINK WHITE SPOTS GARDEN PARASOL [15058B]
... A36: 15060b | B36: FAIRY CAKE DESIGN UMBRELLA | C36: 8.29 | D36: 1 | E36: 1 | F36: 5 | G36: 41.81 | H36: Low Volume | I36: =B36&" ["&A36&"]" -> FAIRY CAKE DESIGN UMBRELLA [15060b]
A37: 16008 | B37: SMALL FOLDING SCISSOR(POINTED EDGE) | C37: 0.25 | D37: 72 | E37: 184.76471 | F37: 17 | G37: 422.96 | H37: High Volume | I37: =B37&" ["&A37&"]" -> SMALL FOLDING SCISSOR(POINTED EDGE) [16008]
A38: 16010 | B38: FOLDING CAMPING SCISSOR W/KNIF & S | C38: 0.12 | D38: 9 | E38: 8 | F38: 4 | G38: 3.84 | H38: Low Volume | I38: =B38&" ["&A38&"]" -> FOLDING CAMPING SCISSOR W/KNIF & S [16010]
A39: 16011 | B39: ANIMAL STICKERS | C39: 0.21 | D39: 147 | E39: 152.48 | F39: 24 | G39: 799.32 | H39: High Volume | I39: =B39&" ["&A39&"]" -> ANIMAL STICKERS [16011]
A40: 16012 | B40: FOOD/DRINK SPUNGE STICKERS | C40: 0.21 | D40: 84 | E40: 131.86364 | F40: 22 | G40: 608.01 | H40: High Volume | I40: =B40&" ["&A40&"]" -> FOOD/DRINK SPUNGE STICKERS [16012]
A41: 16014 | B41: SMALL CHINESE STYLE SCISSOR | C41: 0.33 | D41: 786 | E41: 1223.125 | F41: 24 | G41: 9513.1 | H41: High Volume | I41: =B41&" ["&A41&"]" -> SMALL CHINESE STYLE SCISSOR [16014]
A42: 16015 | B42: MEDIUM CHINESE STYLE SCISSOR | C42: 0.5 | D42: 43 | E42: 74.857143 | F42: 21 | G42: 711.38 | H42: Mid Volume | I42: =B42&" ["&A42&"]" -> MEDIUM CHINESE STYLE SCISSOR [16015]
A43: 16016 | B43: LARGE CHINESE STYLE SCISSOR | C43: 0.85 | D43: 60 | E43: 92.56 | F43: 25 | G43: 1870.7 | H43: Mid Volume | I43: =B43&" ["&A43&"]" -> LARGE CHINESE STYLE SCISSOR [16016]
...
